<?xml version="1.0"?>
<robot name="Kraken">
  <!--gazebo reference="base">
    <material>Gazebo/GrassFloor</material>
  </gazebo-->
  <!--link name="center_auv">
   <inertial>
      <origin xyz="0 0 0" /> 
      <mass value="0.01" />
      <inertia  ixx="0.01" ixy="0.0"  ixz="0.0"  iyy="0.01"  iyz="0.0"  izz="0.01" />
    </inertial>
    <visual>
      <origin xyz="0 0 0"/>
      <geometry>
        <box size=".01 .01 .01" />
      </geometry>
    </visual>
    <collision>
      <origin xyz="0 0 0"/>
      <geometry>
        <box size=".01 .01 .01" />
      </geometry>
    </collision>
  </link>
  <!--gazebo reference="auv">
    <material>Gazebo/Green</material>
    <turnGravityOff>true</turnGravityOff>
  </gazebo-->
  <link name="auv_body">
    <inertial>
      <origin xyz="0 0 0" /> 
      <mass value="35" />
      <inertia  ixx="1" ixy="0.0"  ixz="0.0"  iyy="1"  iyz="0.0"  izz="1" />
    </inertial>
    <visual>
      <origin rpy="0 0 0" xyz="0 0 0"/>
      <geometry>
        <mesh filename="package://auv_visulaization/urdf/AUV/mesh_files/new_model_kraken.stl"/>
      </geometry>
    </visual>
    <collision>
      <origin rpy="0 0 0" xyz="0 0 0"/>
      <geometry>
        <mesh filename="package://auv_visulaization/urdf/AUV/mesh_files/new_model_kraken.stl"/>
      </geometry>
    </collision>
  </link>
  <gazebo reference="auv_body">
    <material>Gazebo/Green</material>
    <turnGravityOff>true</turnGravityOff>
  </gazebo>
  <link name="right_heave_thruster">
    <inertial>
      <origin xyz="0 0 0" /> 
      <mass value="0.01" />
      <inertia  ixx="0.01" ixy="0.0"  ixz="0.0"  iyy="0.01"  iyz="0.0"  izz="0.01" />
    </inertial>
    <visual>
      <origin xyz="0 0 0"/>
      <geometry>
        <box size=".01 .01 .01" />
      </geometry>
    </visual>
    <collision>
      <origin xyz="0 0 0"/>
      <geometry>
        <box size=".01 .01 .01" />
      </geometry>
    </collision>
  </link>
  <gazebo reference="right_heave_thruster">
    <material>Gazebo/Red</material>
    <turnGravityOff>true</turnGravityOff>
  </gazebo>
  <link name="left_heave_thruster">
    <inertial>
      <origin xyz="0 0 0" /> 
      <mass value="0.01" />
      <inertia  ixx="0.01" ixy="0.00"  ixz="0.0"  iyy="0.01"  iyz="0.0"  izz="0.001" />
    </inertial>
    <visual>
      <origin xyz="0 0 0"/>
      <geometry>
        <box size=".01 .01 .01" />
      </geometry>
    </visual>
    <collision>
      <origin xyz="0 0 0"/>
      <geometry>
        <box size=".01 .01 .01" />
      </geometry>
    </collision>
  </link>
  <gazebo reference="left_heave_thruster">
    <material>Gazebo/Red</material>
    <turnGravityOff>true</turnGravityOff>
  </gazebo>
  <link name="right_surge_thruster">
    <inertial>
      <origin xyz="0 0 0" /> 
      <mass value="0.01" />
      <inertia  ixx="0.01" ixy="0.00"  ixz="0.0"  iyy="0.001"  iyz="0.0"  izz="0.01" />
    </inertial>
    <visual>
      <origin xyz="0 0 0"/>
      <geometry>
        <box size=".01 .01 .01" />
      </geometry>
    </visual>
    <collision>
      <origin xyz="0 0 0"/>
      <geometry>
        <box size=".01 .01 .01" />
      </geometry>
    </collision>
  </link>
  <gazebo reference="right_surge_thruster">
    <material>Gazebo/Blue</material>
    <turnGravityOff>true</turnGravityOff>
  </gazebo>
  <link name="left_surge_thruster">
    <inertial>
      <origin xyz="0 0 0" /> 
      <mass value="0.01" />
      <inertia  ixx="0.01" ixy="0.00"  ixz="0.0"  iyy="0.001"  iyz="0.0"  izz="0.01" />
    </inertial>
    <visual>
      <origin xyz="0 0 0"/>
      <geometry>
        <box size=".01 .01 .01" />
      </geometry>
    </visual>
    <collision>
      <origin xyz="0 0 0"/>
      <geometry>
        <box size=".01 .01 .01" />
      </geometry>
    </collision>
  </link>
  <gazebo reference="left_surge_thruster">
    <material>Gazebo/Blue</material>
    <turnGravityOff>true</turnGravityOff>
  </gazebo>
  <link name="camera_front">
  <inertial>
      <origin xyz="0 0 0" /> 
      <mass value="0.01" />
      <inertia  ixx="0.01" ixy="0.00"  ixz="0.0"  iyy="0.001"  iyz="0.0"  izz="0.01" />
    </inertial>
    <visual>
      <origin xyz="0 0 0"/>
      <geometry>
        <box size=".01 .01 .01" />
      </geometry>
    </visual>
    <collision>
      <origin xyz="0 0 0"/>
      <geometry>
        <box size=".01 .01 .01" />
      </geometry>
    </collision>
  </link>
  <joint name="camera_front_to_base_link" type="fixed">
    <parent link="auv_body"/>
    <child link="camera_front"/>
    <axis xyz="0 0 1"/>
    <!--origin rpy="0 0.0 0" xyz="-0.428 -0.17 0.12"/-->
    <origin rpy="0 0.0 0" xyz="0.428 -0.0 0.06"/>
    <limit effort="30" lower="0.0" upper=".01" velocity="2.0"/>
  </joint>
  <!--joint name="auv_body_to_center_auv" type="fixed">
    <parent link="auv_body"/>
    <child link="center_auv"/>
    <axis xyz="0 0 0"/>
    <origin rpy="0 0.0 0" xyz="0 0 0"/>
  </joint>
  <!--transmission name="j0_transmission" type="pr2_mechanism_model/SimpleTransmission">
    <actuator name="j0"/>
    <joint name="auv_body"/>
    <mechanicalReduction>1</mechanicalReduction>
    <motorTorqueConstant>1</motorTorqueConstant>
  </transmission-->
  <joint name="right_heave_thruster_to_base_link" type="revolute">
    <parent link="auv_body"/>
    <child link="right_heave_thruster"/>
    <axis xyz="0 0 1"/>
    <!--origin rpy="0 0.0 0" xyz="-0.428 -0.17 0.12"/-->
    <origin rpy="0 0.0 0" xyz="-0.0 -0.37 0.06"/>
    <limit effort="30" lower="0.0" upper=".01" velocity="2.0"/>
  </joint>
  <transmission name="j1_transmission" type="pr2_mechanism_model/SimpleTransmission">
    <actuator name="j1"/>
    <joint name="right_heave_thruster_to_base_link"/>
    <mechanicalReduction>1</mechanicalReduction>
    <motorTorqueConstant>1</motorTorqueConstant>
  </transmission>
  <joint name="left_heave_thruster_to_base_link" type="revolute">
    <parent link="auv_body"/>
    <child link="left_heave_thruster"/>
    <axis xyz="0 0 1"/>
    <!--origin rpy="0 0.0 0" xyz="-0.428 0.17 0.12"/-->
    <origin rpy="0 0.0 0" xyz="-0.0 0.37 0.06"/>
    <limit effort="30" lower="0.0" upper=".01" velocity="2.0"/>
  </joint>
  <transmission name="j2_transmission" type="pr2_mechanism_model/SimpleTransmission">
    <actuator name="j2"/>
    <joint name="left_heave_thruster_to_base_link"/>
    <mechanicalReduction>1</mechanicalReduction>
    <motorTorqueConstant>1</motorTorqueConstant>
  </transmission>
  <joint name="right_surge_thruster_to_base_link" type="revolute">
    <parent link="auv_body"/>
    <child link="right_surge_thruster"/>
    <axis xyz="-1 0 0"/>
    <!--origin rpy="0 0.0 0" xyz="-0.88 -0.17 0.06"/-->
    <origin rpy="0 0.0 0" xyz="-0.452 -0.37 0.00"/>
    <limit effort="30" lower="0.0" upper=".01" velocity="2.0"/>
  </joint>
  <transmission name="j3_transmission" type="pr2_mechanism_model/SimpleTransmission">
    <actuator name="j3"/>
    <joint name="right_surge_thruster_to_base_link"/>
    <mechanicalReduction>1</mechanicalReduction>
    <motorTorqueConstant>1</motorTorqueConstant>
  </transmission>
  <joint name="left_surge_thruster_to_base_link" type="revolute">
    <parent link="auv_body"/>
    <child link="left_surge_thruster"/>
    <axis xyz="-1 0 0"/>
    <origin rpy="0 0.0 0" xyz="-0.452 0.37 0.00"/>
    <limit effort="30" lower="0.0" upper=".01" velocity="2.0"/>
    <!--origin rpy="0 0.0 0" xyz="-0.88 0.17 0.06"/-->
  </joint>
  <transmission name="j4_transmission" type="pr2_mechanism_model/SimpleTransmission">
    <actuator name="j4"/>
    <joint name="left_surge_thruster_to_base_link"/>
    <mechanicalReduction>1</mechanicalReduction>
    <motorTorqueConstant>1</motorTorqueConstant>
  </transmission>
  <gazebo>
    <controller:gazebo_ros_force name="left_heave_thruster_force" plugin="libgazebo_ros_force.so">
      <alwaysOn>true</alwaysOn>
      <update>100</update>
      <updateRate>100.0</updateRate>
      <bodyName>left_heave_thruster</bodyName>
      <topicName>heave_thruster/force</topicName>
    </controller:gazebo_ros_force>
    <controller:gazebo_ros_force name="right_heave_thruster_force" plugin="libgazebo_ros_force.so">
      <alwaysOn>true</alwaysOn>
      <update>100</update>
      <updateRate>100.0</updateRate>
      <bodyName>right_heave_thruster</bodyName>
      <topicName>heave_thruster/force</topicName>
    </controller:gazebo_ros_force>
    <controller:gazebo_ros_force name="right_surge_thruster_force" plugin="libgazebo_ros_force.so">
      <alwaysOn>true</alwaysOn>
      <update>100</update>
      <updateRate>100.0</updateRate>
      <bodyName>right_surge_thruster</bodyName>
      <topicName>right_surge_thruster/force</topicName>
    </controller:gazebo_ros_force>
    <controller:gazebo_ros_force name="left_surge_thruster_force" plugin="libgazebo_ros_force.so">
      <alwaysOn>true</alwaysOn>
      <update>100</update>
      <updateRate>100.0</updateRate>
      <bodyName>left_surge_thruster</bodyName>
      <topicName>left_surge_thruster/force</topicName>
    </controller:gazebo_ros_force>
  </gazebo>
  <gazebo reference="camera_front">
    <material>Gazebo/Red</material>
    <turnGravityOff>true</turnGravityOff>
    <sensor:camera name="front_camera">
      <imageFormat>R8G8B8</imageFormat>
      <imageSize>400 300</imageSize>
      <hfov>45</hfov>
      <nearClip>0.1</nearClip>
      <farClip>100</farClip>
      <updateRate>2.0</updateRate>
      <controller:gazebo_ros_depth_camera name="front_cam" plugin="libgazebo_ros_depth_camera.so">
        <alwaysOn>true</alwaysOn>
        <updateRate>2.0</updateRate>
        <cameraName>cam_front</cameraName>
        <imageTopicName>/front_cam/image_raw</imageTopicName>
        <cameraInfoTopicName>/front_cam/camera_info</cameraInfoTopicName>
        <pollServiceName>/front_cam/request_image</pollServiceName>
        <frameName>camera_front</frameName>
        <CxPrime>2005</CxPrime>
        <Cx>200.5</Cx>
        <Cy>150.5</Cy>
        <focal_length>2955</focal_length> <!-- image_width / (2*tan(hfov_radian /2)) -->
        <distortion_k1>0.00000000</distortion_k1>
        <distortion_k2>0.00000000</distortion_k2>
        <distortion_k3>0.00000000</distortion_k3>
        <distortion_t1>0.00000000</distortion_t1>
        <distortion_t2>0.00000000</distortion_t2>
        <interface:camera name="front_cam_interface"/>
      </controller:gazebo_ros_depth_camera>
    </sensor:camera>
  </gazebo>
</robot>
